

### 方法一：设置sys的异常钩子函数

如果之前配置过logging

调用`logging.error()`的时候会将报错信息保存到日志文件。

```python
import sys
import logging


def callback_func(exc_type, exc_value, exc_traceback):
    logging.error("callback_func>>>>>>>>>>>>>>", exc_info=(
        exc_type, exc_value, exc_traceback))


sys.excepthook = callback_func
1 / 0

```

```
---------------------------------------------------------------------------
ZeroDivisionError                         Traceback (most recent call last)
~\tmp.py in <module>
      9 
     10 sys.excepthook = callback_func
---> 11 1 / 0

ZeroDivisionError: division by zero
```

### 方法二：使用try except捕获并显示错误

```python
import logging
import sys

try:
    1 / 0
except Exception as e:
    exc_type, exc_value, exc_traceback = sys.exc_info()
    logging.error("callback_func>>>>>>>>>>>>>>", exc_info=(
        exc_type, exc_value, exc_traceback))
```

```
ERROR:root:callback_func>>>>>>>>>>>>>>
Traceback (most recent call last):
  File "C:\Users\tmp.py", line 5, in <module>
    1 / 0
ZeroDivisionError: division by zero
```



### 方法三：直接使用`logging.exception()`

```python
import logging
try:
    1 / 0
except:
    logging.exception('除0错误!')
```

```
ERROR:root:除0错误!
Traceback (most recent call last):
  File "C:\Users\tmp.py", line 3, in <module>
    1 / 0
ZeroDivisionError: division by zero
```

