如果之前配置过logging，会根据具体情况保存到日志文件内。

```python
import sys
import logging


def callback_func(exc_type, exc_value, exc_traceback):
    logging.error("callback_func>>>>>>>>>>>>>>", exc_info=(
        exc_type, exc_value, exc_traceback))


sys.excepthook = callback_func
1 / 0

```

```
---------------------------------------------------------------------------
ZeroDivisionError                         Traceback (most recent call last)
~\tmp.py in <module>
      9 
     10 sys.excepthook = callback_func
---> 11 1 / 0

ZeroDivisionError: division by zero
```



```python
import logging
import sys

try:
    1 / 0
except Exception as e:
    exc_type, exc_value, exc_traceback = sys.exc_info()
    logging.error("callback_func>>>>>>>>>>>>>>", exc_info=(
        exc_type, exc_value, exc_traceback))
```

```
ERROR:root:callback_func>>>>>>>>>>>>>>
Traceback (most recent call last):
  File "C:\Users\tmp.py", line 5, in <module>
    1 / 0
ZeroDivisionError: division by zero
```



或者用另一种方式

```python
import logging
try:
    1 / 0
except:
    logging.exception('除0错误!')
```

```
ERROR:root:除0错误!
Traceback (most recent call last):
  File "C:\Users\tmp.py", line 3, in <module>
    1 / 0
ZeroDivisionError: division by zero
```

